Traceback (most recent call last):
  File "C:\Users\ibhan\miniconda3\envs\mfbook_310\lib\site-packages\jupyter_cache\executors\utils.py", line 58, in single_nb_execution
    executenb(
  File "C:\Users\ibhan\miniconda3\envs\mfbook_310\lib\site-packages\nbclient\client.py", line 1305, in execute
    return NotebookClient(nb=nb, resources=resources, km=km, **kwargs).execute()
  File "C:\Users\ibhan\miniconda3\envs\mfbook_310\lib\site-packages\jupyter_core\utils\__init__.py", line 166, in wrapped
    return loop.run_until_complete(inner)
  File "C:\Users\ibhan\miniconda3\envs\mfbook_310\lib\asyncio\base_events.py", line 649, in run_until_complete
    return future.result()
  File "C:\Users\ibhan\miniconda3\envs\mfbook_310\lib\site-packages\nbclient\client.py", line 705, in async_execute
    await self.async_execute_cell(
  File "C:\Users\ibhan\miniconda3\envs\mfbook_310\lib\site-packages\nbclient\client.py", line 1058, in async_execute_cell
    await self._check_raise_for_error(cell, cell_index, exec_reply)
  File "C:\Users\ibhan\miniconda3\envs\mfbook_310\lib\site-packages\nbclient\client.py", line 914, in _check_raise_for_error
    raise CellExecutionError.from_cell_and_msg(cell, exec_reply_content)
nbclient.exceptions.CellExecutionError: An error occurred while executing the following cell:
------------------
mpak['PAKNYGDPMKTPKN PAKNECONPRVTKN'].draw(up=1,down=1,png=latex)  # diagram of all direct dependencies 
------------------


[1;31m---------------------------------------------------------------------------[0m
[1;31mNameError[0m                                 Traceback (most recent call last)
Cell [1;32mIn[41], line 1[0m
[1;32m----> 1[0m mpak[[38;5;124m'[39m[38;5;124mPAKNYGDPMKTPKN PAKNECONPRVTKN[39m[38;5;124m'[39m][38;5;241m.[39mdraw(up[38;5;241m=[39m[38;5;241m1[39m,down[38;5;241m=[39m[38;5;241m1[39m,png[38;5;241m=[39m[43mlatex[49m)  [38;5;66;03m# diagram of all direct dependencies [39;00m

[1;31mNameError[0m: name 'latex' is not defined

