Traceback (most recent call last):
  File "C:\Users\ibhan\miniconda3\envs\mfbook\lib\site-packages\jupyter_cache\executors\utils.py", line 51, in single_nb_execution
    executenb(
  File "C:\Users\ibhan\miniconda3\envs\mfbook\lib\site-packages\nbclient\client.py", line 1204, in execute
    return NotebookClient(nb=nb, resources=resources, km=km, **kwargs).execute()
  File "C:\Users\ibhan\miniconda3\envs\mfbook\lib\site-packages\nbclient\util.py", line 84, in wrapped
    return just_run(coro(*args, **kwargs))
  File "C:\Users\ibhan\miniconda3\envs\mfbook\lib\site-packages\nbclient\util.py", line 62, in just_run
    return loop.run_until_complete(coro)
  File "C:\Users\ibhan\miniconda3\envs\mfbook\lib\asyncio\base_events.py", line 647, in run_until_complete
    return future.result()
  File "C:\Users\ibhan\miniconda3\envs\mfbook\lib\site-packages\nbclient\client.py", line 663, in async_execute
    await self.async_execute_cell(
  File "C:\Users\ibhan\miniconda3\envs\mfbook\lib\site-packages\nbclient\client.py", line 965, in async_execute_cell
    await self._check_raise_for_error(cell, cell_index, exec_reply)
  File "C:\Users\ibhan\miniconda3\envs\mfbook\lib\site-packages\nbclient\client.py", line 862, in _check_raise_for_error
    raise CellExecutionError.from_cell_and_msg(cell, exec_reply_content)
nbclient.exceptions.CellExecutionError: An error occurred while executing the following cell:
------------------
mfrbusmce['dmp*'].df
------------------

[1;31m---------------------------------------------------------------------------[0m
[1;31mKeyError[0m                                  Traceback (most recent call last)
[1;32mC:\modelflow2\modelflow\modelclass.py[0m in [0;36m__getattr__[1;34m(self, name)[0m
[0;32m   1236[0m         [1;32mtry[0m[1;33m:[0m[1;33m[0m[1;33m[0m[0m
[1;32m-> 1237[1;33m             [1;32mreturn[0m [0mmv[0m[1;33m.[0m[0mvarvis[0m[1;33m([0m[0mmodel[0m[1;33m=[0m[0mself[0m[1;33m,[0m [0mvar[0m[1;33m=[0m[0mname[0m[1;33m.[0m[0mupper[0m[1;33m([0m[1;33m)[0m[1;33m)[0m[1;33m[0m[1;33m[0m[0m
[0m[0;32m   1238[0m         [1;32mexcept[0m[1;33m:[0m[1;33m[0m[1;33m[0m[0m

[1;32mC:\modelflow2\modelflow\modelvis.py[0m in [0;36m__init__[1;34m(self, model, var)[0m
[0;32m    307[0m          [0mself[0m[1;33m.[0m[0mvar[0m [1;33m=[0m [0mvar[0m[1;33m[0m[1;33m[0m[0m
[1;32m--> 308[1;33m          [0mself[0m[1;33m.[0m[0mendo[0m [1;33m=[0m [0mself[0m[1;33m.[0m[0mmodel[0m[1;33m.[0m[0mallvar[0m[1;33m[[0m[0mvar[0m[1;33m][0m[1;33m[[0m[1;34m'endo'[0m[1;33m][0m[1;33m[0m[1;33m[0m[0m
[0m[0;32m    309[0m [1;33m[0m[0m

[1;31mKeyError[0m: 'LASTDF'

During handling of the above exception, another exception occurred:

[1;31mAttributeError[0m                            Traceback (most recent call last)
[1;32m~\AppData\Local\Temp\ipykernel_22652\4240144748.py[0m in [0;36m<cell line: 1>[1;34m()[0m
[1;32m----> 1[1;33m [0mmfrbusmce[0m[1;33m[[0m[1;34m'dmp*'[0m[1;33m][0m[1;33m.[0m[0mdf[0m[1;33m[0m[1;33m[0m[0m
[0m
[1;32mC:\modelflow2\modelflow\modelclass.py[0m in [0;36m__getitem__[1;34m(self, name)[0m
[0;32m   1225[0m [1;33m[0m[0m
[0;32m   1226[0m         '''
[1;32m-> 1227[1;33m         [0ma[0m [1;33m=[0m [0mself[0m[1;33m.[0m[0mvis[0m[1;33m([0m[0mname[0m[1;33m)[0m[1;33m[0m[1;33m[0m[0m
[0m[0;32m   1228[0m         [1;32mreturn[0m [0ma[0m[1;33m[0m[1;33m[0m[0m
[0;32m   1229[0m [1;33m[0m[0m

[1;32mC:\modelflow2\modelflow\modelclass.py[0m in [0;36mvis[1;34m(self, *args, **kwargs)[0m
[0;32m   3564[0m         [1;32mif[0m [1;32mnot[0m [0mhasattr[0m[1;33m([0m[0mself[0m[1;33m,[0m [1;34m'_vis'[0m[1;33m)[0m[1;33m:[0m[1;33m[0m[1;33m[0m[0m
[0;32m   3565[0m             [0mself[0m[1;33m.[0m[0m_vis[0m [1;33m=[0m [0mmv[0m[1;33m.[0m[0mvis[0m[1;33m[0m[1;33m[0m[0m
[1;32m-> 3566[1;33m         [1;32mreturn[0m [0mself[0m[1;33m.[0m[0m_vis[0m[1;33m([0m[0mself[0m[1;33m,[0m [1;33m*[0m[0margs[0m[1;33m,[0m [1;33m**[0m[0mkwargs[0m[1;33m)[0m[1;33m[0m[1;33m[0m[0m
[0m[0;32m   3567[0m [1;33m[0m[0m
[0;32m   3568[0m     [1;32mdef[0m [0mvarvis[0m[1;33m([0m[0mself[0m[1;33m,[0m [1;33m*[0m[0margs[0m[1;33m,[0m [1;33m**[0m[0mkwargs[0m[1;33m)[0m[1;33m:[0m[1;33m[0m[1;33m[0m[0m

[1;32mC:\modelflow2\modelflow\modelvis.py[0m in [0;36m__init__[1;34m(self, model, pat, names, df)[0m
[0;32m     51[0m              [0mself[0m[1;33m.[0m[0mthisdf[0m [1;33m=[0m [0mdf[0m[1;33m[0m[1;33m[0m[0m
[0;32m     52[0m          [1;32melse[0m[1;33m:[0m[1;33m[0m[1;33m[0m[0m
[1;32m---> 53[1;33m              [0mself[0m[1;33m.[0m[0mthisdf[0m [1;33m=[0m [0mself[0m[1;33m.[0m[0mmodel[0m[1;33m.[0m[0mlastdf[0m[1;33m.[0m[0mloc[0m[1;33m[[0m[1;33m:[0m[1;33m,[0m[0mself[0m[1;33m.[0m[0mnames[0m[1;33m][0m[1;33m[0m[1;33m[0m[0m
[0m[0;32m     54[0m          [1;32mreturn[0m[1;33m[0m[1;33m[0m[0m
[0;32m     55[0m [1;33m[0m[0m

[1;32mC:\modelflow2\modelflow\modelclass.py[0m in [0;36m__getattr__[1;34m(self, name)[0m
[0;32m   1238[0m         [1;32mexcept[0m[1;33m:[0m[1;33m[0m[1;33m[0m[0m
[0;32m   1239[0m             [1;31m#            print(name)[0m[1;33m[0m[1;33m[0m[0m
[1;32m-> 1240[1;33m             [1;32mraise[0m [0mAttributeError[0m[1;33m[0m[1;33m[0m[0m
[0m[0;32m   1241[0m             [1;32mpass[0m[1;33m[0m[1;33m[0m[0m
[0;32m   1242[0m [1;33m[0m[0m

[1;31mAttributeError[0m: 
AttributeError: 

