Traceback (most recent call last):
  File "C:\Users\ibhan\miniconda3\envs\mf\lib\site-packages\jupyter_cache\executors\utils.py", line 51, in single_nb_execution
    executenb(
  File "C:\Users\ibhan\miniconda3\envs\mf\lib\site-packages\nbclient\client.py", line 1204, in execute
    return NotebookClient(nb=nb, resources=resources, km=km, **kwargs).execute()
  File "C:\Users\ibhan\miniconda3\envs\mf\lib\site-packages\nbclient\util.py", line 84, in wrapped
    return just_run(coro(*args, **kwargs))
  File "C:\Users\ibhan\miniconda3\envs\mf\lib\site-packages\nbclient\util.py", line 62, in just_run
    return loop.run_until_complete(coro)
  File "C:\Users\ibhan\miniconda3\envs\mf\lib\asyncio\base_events.py", line 647, in run_until_complete
    return future.result()
  File "C:\Users\ibhan\miniconda3\envs\mf\lib\site-packages\nbclient\client.py", line 663, in async_execute
    await self.async_execute_cell(
  File "C:\Users\ibhan\miniconda3\envs\mf\lib\site-packages\nbclient\client.py", line 965, in async_execute_cell
    await self._check_raise_for_error(cell, cell_index, exec_reply)
  File "C:\Users\ibhan\miniconda3\envs\mf\lib\site-packages\nbclient\client.py", line 862, in _check_raise_for_error
    raise CellExecutionError.from_cell_and_msg(cell, exec_reply_content)
nbclient.exceptions.CellExecutionError: An error occurred while executing the following cell:
------------------
mftt.group_dict = {
    'share*' : 'Shares',
    'c_t*'   :  'Cost' ,
    'useful*':  'Demand'
    ''
    '*'      :  'all'
}
------------------

[1;36m  Cell [1;32mIn[13], line 6[1;36m[0m
[1;33m    '*'      :  'all'[0m
[1;37m             ^[0m
[1;31mSyntaxError[0m[1;31m:[0m invalid syntax

SyntaxError: invalid syntax (2692135562.py, line 6)

