Traceback (most recent call last):
  File "C:\Users\ibhan\Anaconda3\envs\mf\lib\site-packages\jupyter_cache\executors\utils.py", line 51, in single_nb_execution
    executenb(
  File "C:\Users\ibhan\Anaconda3\envs\mf\lib\site-packages\nbclient\client.py", line 1204, in execute
    return NotebookClient(nb=nb, resources=resources, km=km, **kwargs).execute()
  File "C:\Users\ibhan\Anaconda3\envs\mf\lib\site-packages\nbclient\util.py", line 84, in wrapped
    return just_run(coro(*args, **kwargs))
  File "C:\Users\ibhan\Anaconda3\envs\mf\lib\site-packages\nbclient\util.py", line 62, in just_run
    return loop.run_until_complete(coro)
  File "C:\Users\ibhan\Anaconda3\envs\mf\lib\asyncio\base_events.py", line 642, in run_until_complete
    return future.result()
  File "C:\Users\ibhan\Anaconda3\envs\mf\lib\site-packages\nbclient\client.py", line 663, in async_execute
    await self.async_execute_cell(
  File "C:\Users\ibhan\Anaconda3\envs\mf\lib\site-packages\nbclient\client.py", line 965, in async_execute_cell
    await self._check_raise_for_error(cell, cell_index, exec_reply)
  File "C:\Users\ibhan\Anaconda3\envs\mf\lib\site-packages\nbclient\client.py", line 862, in _check_raise_for_error
    raise CellExecutionError.from_cell_and_msg(cell, exec_reply_content)
nbclient.exceptions.CellExecutionError: An error occurred while executing the following cell:
------------------
with mpak.set_smpl(2022,2026):
    mpak.modeldash('PAKNYGDPMKTPKN',jupyter=True,inline=False)  # delete # if running a live notebook 
------------------

[1;31m---------------------------------------------------------------------------[0m
[1;31mModuleNotFoundError[0m                       Traceback (most recent call last)
Input [1;32mIn [13][0m, in [0;36m<module>[1;34m[0m
[0;32m      1[0m [38;5;28;01mwith[39;00m mpak[38;5;241m.[39mset_smpl([38;5;241m2022[39m,[38;5;241m2026[39m):
[1;32m----> 2[0m     [43mmpak[49m[38;5;241;43m.[39;49m[43mmodeldash[49m[43m([49m[38;5;124;43m'[39;49m[38;5;124;43mPAKNYGDPMKTPKN[39;49m[38;5;124;43m'[39;49m[43m,[49m[43mjupyter[49m[38;5;241;43m=[39;49m[38;5;28;43;01mTrue[39;49;00m[43m,[49m[43minline[49m[38;5;241;43m=[39;49m[38;5;28;43;01mFalse[39;49;00m[43m)[49m

File [1;32mC:\modelflow2\modelflow\modelclass.py:6321[0m, in [0;36mDash_Mixin.modeldash[1;34m(self, *arg, **kwargs)[0m
[0;32m   6320[0m [38;5;28;01mdef[39;00m [38;5;21mmodeldash[39m([38;5;28mself[39m,[38;5;241m*[39marg,[38;5;241m*[39m[38;5;241m*[39mkwargs):
[1;32m-> 6321[0m     [38;5;28;01mfrom[39;00m [38;5;21;01mmodeldashsidebar[39;00m [38;5;28;01mimport[39;00m Dash_graph
[0;32m   6322[0m     [38;5;241m.[39m[38;5;241m.[39m[38;5;241m.[39m
[0;32m   6323[0m     out [38;5;241m=[39m Dash_graph([38;5;28mself[39m,[38;5;241m*[39marg,[38;5;241m*[39m[38;5;241m*[39mkwargs)

File [1;32mC:\modelflow2\modelflow\modeldashsidebar.py:25[0m, in [0;36m<module>[1;34m[0m
[0;32m     22[0m [38;5;28;01mfrom[39;00m [38;5;21;01mdash[39;00m[38;5;21;01m.[39;00m[38;5;21;01mdependencies[39;00m [38;5;28;01mimport[39;00m Input, Output, State
[0;32m     23[0m [38;5;28;01mfrom[39;00m [38;5;21;01mdash[39;00m[38;5;21;01m.[39;00m[38;5;21;01mexceptions[39;00m [38;5;28;01mimport[39;00m PreventUpdate
[1;32m---> 25[0m [38;5;28;01mfrom[39;00m  [38;5;21;01mdash_interactive_graphviz[39;00m [38;5;28;01mimport[39;00m DashInteractiveGraphviz
[0;32m     27[0m [38;5;28;01mimport[39;00m [38;5;21;01mplotly[39;00m[38;5;21;01m.[39;00m[38;5;21;01mgraph_objs[39;00m [38;5;28;01mas[39;00m [38;5;21;01mgo[39;00m
[0;32m     28[0m [38;5;28;01mfrom[39;00m [38;5;21;01mplotly[39;00m[38;5;21;01m.[39;00m[38;5;21;01mgraph_objs[39;00m[38;5;21;01m.[39;00m[38;5;21;01mscatter[39;00m[38;5;21;01m.[39;00m[38;5;21;01mmarker[39;00m [38;5;28;01mimport[39;00m Line

[1;31mModuleNotFoundError[0m: No module named 'dash_interactive_graphviz'
ModuleNotFoundError: No module named 'dash_interactive_graphviz'

