Traceback (most recent call last):
  File "C:\Users\ibhan\Anaconda3\envs\mf\lib\site-packages\jupyter_cache\executors\utils.py", line 51, in single_nb_execution
    executenb(
  File "C:\Users\ibhan\Anaconda3\envs\mf\lib\site-packages\nbclient\client.py", line 1204, in execute
    return NotebookClient(nb=nb, resources=resources, km=km, **kwargs).execute()
  File "C:\Users\ibhan\Anaconda3\envs\mf\lib\site-packages\nbclient\util.py", line 84, in wrapped
    return just_run(coro(*args, **kwargs))
  File "C:\Users\ibhan\Anaconda3\envs\mf\lib\site-packages\nbclient\util.py", line 62, in just_run
    return loop.run_until_complete(coro)
  File "C:\Users\ibhan\Anaconda3\envs\mf\lib\asyncio\base_events.py", line 642, in run_until_complete
    return future.result()
  File "C:\Users\ibhan\Anaconda3\envs\mf\lib\site-packages\nbclient\client.py", line 663, in async_execute
    await self.async_execute_cell(
  File "C:\Users\ibhan\Anaconda3\envs\mf\lib\site-packages\nbclient\client.py", line 965, in async_execute_cell
    await self._check_raise_for_error(cell, cell_index, exec_reply)
  File "C:\Users\ibhan\Anaconda3\envs\mf\lib\site-packages\nbclient\client.py", line 862, in _check_raise_for_error
    raise CellExecutionError.from_cell_and_msg(cell, exec_reply_content)
nbclient.exceptions.CellExecutionError: An error occurred while executing the following cell:
------------------
mpak,result = model.modelload('../models/pak.pcim',run=1,silent=1)
------------------

[1;31m---------------------------------------------------------------------------[0m
[1;31mFileNotFoundError[0m                         Traceback (most recent call last)
Input [1;32mIn [3][0m, in [0;36m<module>[1;34m[0m
[1;32m----> 1[0m mpak,result [38;5;241m=[39m [43mmodel[49m[38;5;241;43m.[39;49m[43mmodelload[49m[43m([49m[38;5;124;43m'[39;49m[38;5;124;43m../models/pak.pcim[39;49m[38;5;124;43m'[39;49m[43m,[49m[43mrun[49m[38;5;241;43m=[39;49m[38;5;241;43m1[39;49m[43m,[49m[43msilent[49m[38;5;241;43m=[39;49m[38;5;241;43m1[39;49m[43m)[49m

File [1;32mC:\modelflow2\modelflow\modelclass.py:4229[0m, in [0;36mJson_Mixin.modelload[1;34m(cls, infile, funks, run, keep_json, **kwargs)[0m
[0;32m   4226[0m     base[38;5;241m.[39mindex [38;5;241m=[39m base_dates
[0;32m   4227[0m     [38;5;28;01mreturn[39;00m base, current_dates
[1;32m-> 4229[0m [38;5;28;01mwith[39;00m [38;5;28;43mopen[39;49m[43m([49m[43minfile[49m[43m,[49m[43m [49m[38;5;124;43m'[39;49m[38;5;124;43mrt[39;49m[38;5;124;43m'[39;49m[43m)[49m [38;5;28;01mas[39;00m f:
[0;32m   4230[0m     [38;5;28minput[39m [38;5;241m=[39m json[38;5;241m.[39mload(f)
[0;32m   4232[0m version [38;5;241m=[39m [38;5;28minput[39m[[38;5;124m'[39m[38;5;124mversion[39m[38;5;124m'[39m]

[1;31mFileNotFoundError[0m: [Errno 2] No such file or directory: '../models/pak.pcim'
FileNotFoundError: [Errno 2] No such file or directory: '../models/pak.pcim'

