Traceback (most recent call last):
  File "C:\Users\ibhan\anaconda3\envs\mfdoc39\lib\site-packages\jupyter_cache\executors\utils.py", line 51, in single_nb_execution
    executenb(
  File "C:\Users\ibhan\anaconda3\envs\mfdoc39\lib\site-packages\nbclient\client.py", line 1204, in execute
    return NotebookClient(nb=nb, resources=resources, km=km, **kwargs).execute()
  File "C:\Users\ibhan\anaconda3\envs\mfdoc39\lib\site-packages\nbclient\util.py", line 84, in wrapped
    return just_run(coro(*args, **kwargs))
  File "C:\Users\ibhan\anaconda3\envs\mfdoc39\lib\site-packages\nbclient\util.py", line 62, in just_run
    return loop.run_until_complete(coro)
  File "C:\Users\ibhan\anaconda3\envs\mfdoc39\lib\asyncio\base_events.py", line 647, in run_until_complete
    return future.result()
  File "C:\Users\ibhan\anaconda3\envs\mfdoc39\lib\site-packages\nbclient\client.py", line 663, in async_execute
    await self.async_execute_cell(
  File "C:\Users\ibhan\anaconda3\envs\mfdoc39\lib\site-packages\nbclient\client.py", line 965, in async_execute_cell
    await self._check_raise_for_error(cell, cell_index, exec_reply)
  File "C:\Users\ibhan\anaconda3\envs\mfdoc39\lib\site-packages\nbclient\client.py", line 862, in _check_raise_for_error
    raise CellExecutionError.from_cell_and_msg(cell, exec_reply_content)
nbclient.exceptions.CellExecutionError: An error occurred while executing the following cell:
------------------
mpak,baseline = model.modelload('../../models/pak.pcim',alfa=0.7,run=1,keep='Business as Usual')
alternative  =  baseline.upd("<2020 2100> PAKGGREVCO2CER PAKGGREVCO2GER PAKGGREVCO2OER = 29")
result = mpak(alternative,2020,2100,keep='Carbon tax nominal 29') # simulates the model 
------------------

[1;31m---------------------------------------------------------------------------[0m
[1;31mAttributeError[0m                            Traceback (most recent call last)
Cell [1;32mIn [3], line 2[0m
[0;32m      1[0m mpak,baseline [38;5;241m=[39m model[38;5;241m.[39mmodelload([38;5;124m'[39m[38;5;124m../../models/pak.pcim[39m[38;5;124m'[39m,alfa[38;5;241m=[39m[38;5;241m0.7[39m,run[38;5;241m=[39m[38;5;241m1[39m,keep[38;5;241m=[39m[38;5;124m'[39m[38;5;124mBusiness as Usual[39m[38;5;124m'[39m)
[1;32m----> 2[0m alternative  [38;5;241m=[39m  baseline[38;5;241m.[39mupd([38;5;124m"[39m[38;5;124m<2020 2100> PAKGGREVCO2CER PAKGGREVCO2GER PAKGGREVCO2OER = 29[39m[38;5;124m"[39m)
[0;32m      3[0m result [38;5;241m=[39m mpak(alternative,[38;5;241m2020[39m,[38;5;241m2100[39m,keep[38;5;241m=[39m[38;5;124m'[39m[38;5;124mCarbon tax nominal 29[39m[38;5;124m'[39m)

File [1;32m~\anaconda3\envs\mfdoc39\lib\site-packages\pandas\core\generic.py:5907[0m, in [0;36mNDFrame.__getattr__[1;34m(self, name)[0m
[0;32m   5900[0m [38;5;28;01mif[39;00m (
[0;32m   5901[0m     name [38;5;129;01mnot[39;00m [38;5;129;01min[39;00m [38;5;28mself[39m[38;5;241m.[39m_internal_names_set
[0;32m   5902[0m     [38;5;129;01mand[39;00m name [38;5;129;01mnot[39;00m [38;5;129;01min[39;00m [38;5;28mself[39m[38;5;241m.[39m_metadata
[0;32m   5903[0m     [38;5;129;01mand[39;00m name [38;5;129;01mnot[39;00m [38;5;129;01min[39;00m [38;5;28mself[39m[38;5;241m.[39m_accessors
[0;32m   5904[0m     [38;5;129;01mand[39;00m [38;5;28mself[39m[38;5;241m.[39m_info_axis[38;5;241m.[39m_can_hold_identifiers_and_holds_name(name)
[0;32m   5905[0m ):
[0;32m   5906[0m     [38;5;28;01mreturn[39;00m [38;5;28mself[39m[name]
[1;32m-> 5907[0m [38;5;28;01mreturn[39;00m [38;5;28;43mobject[39;49m[38;5;241;43m.[39;49m[38;5;21;43m__getattribute__[39;49m[43m([49m[38;5;28;43mself[39;49m[43m,[49m[43m [49m[43mname[49m[43m)[49m

[1;31mAttributeError[0m: 'DataFrame' object has no attribute 'upd'
AttributeError: 'DataFrame' object has no attribute 'upd'

