Traceback (most recent call last):
  File "C:\Users\ibhan\anaconda3\envs\mfdoc39\lib\site-packages\jupyter_cache\executors\utils.py", line 51, in single_nb_execution
    executenb(
  File "C:\Users\ibhan\anaconda3\envs\mfdoc39\lib\site-packages\nbclient\client.py", line 1204, in execute
    return NotebookClient(nb=nb, resources=resources, km=km, **kwargs).execute()
  File "C:\Users\ibhan\anaconda3\envs\mfdoc39\lib\site-packages\nbclient\util.py", line 84, in wrapped
    return just_run(coro(*args, **kwargs))
  File "C:\Users\ibhan\anaconda3\envs\mfdoc39\lib\site-packages\nbclient\util.py", line 62, in just_run
    return loop.run_until_complete(coro)
  File "C:\Users\ibhan\anaconda3\envs\mfdoc39\lib\asyncio\base_events.py", line 647, in run_until_complete
    return future.result()
  File "C:\Users\ibhan\anaconda3\envs\mfdoc39\lib\site-packages\nbclient\client.py", line 663, in async_execute
    await self.async_execute_cell(
  File "C:\Users\ibhan\anaconda3\envs\mfdoc39\lib\site-packages\nbclient\client.py", line 965, in async_execute_cell
    await self._check_raise_for_error(cell, cell_index, exec_reply)
  File "C:\Users\ibhan\anaconda3\envs\mfdoc39\lib\site-packages\nbclient\client.py", line 862, in _check_raise_for_error
    raise CellExecutionError.from_cell_and_msg(cell, exec_reply_content)
nbclient.exceptions.CellExecutionError: An error occurred while executing the following cell:
------------------
scenarios = {value: 
    baseline.upd(f"<2020:2100> PAKGGREVCO2CER PAKGGREVCO2GER PAKGGREVCO2OER = {value}") 
    for value in [5, 10, 15, 20,25]}
# scenario_30 =     baseline.upd("<2020:2100> PAKGGREVCO2CER PAKGGREVCO2GER PAKGGREVCO2OER = 30") 

------------------

[1;31m---------------------------------------------------------------------------[0m
[1;31mAttributeError[0m                            Traceback (most recent call last)
Cell [1;32mIn [4], line 1[0m
[1;32m----> 1[0m scenarios [38;5;241m=[39m {value: 
[0;32m      2[0m     baseline[38;5;241m.[39mupd([38;5;124mf[39m[38;5;124m"[39m[38;5;124m<2020:2100> PAKGGREVCO2CER PAKGGREVCO2GER PAKGGREVCO2OER = [39m[38;5;132;01m{[39;00mvalue[38;5;132;01m}[39;00m[38;5;124m"[39m) 
[0;32m      3[0m     [38;5;28;01mfor[39;00m value [38;5;129;01min[39;00m [[38;5;241m5[39m, [38;5;241m10[39m, [38;5;241m15[39m, [38;5;241m20[39m,[38;5;241m25[39m]}

Cell [1;32mIn [4], line 2[0m, in [0;36m<dictcomp>[1;34m(.0)[0m
[0;32m      1[0m scenarios [38;5;241m=[39m {value: 
[1;32m----> 2[0m     [43mbaseline[49m[38;5;241;43m.[39;49m[43mupd[49m([38;5;124mf[39m[38;5;124m"[39m[38;5;124m<2020:2100> PAKGGREVCO2CER PAKGGREVCO2GER PAKGGREVCO2OER = [39m[38;5;132;01m{[39;00mvalue[38;5;132;01m}[39;00m[38;5;124m"[39m) 
[0;32m      3[0m     [38;5;28;01mfor[39;00m value [38;5;129;01min[39;00m [[38;5;241m5[39m, [38;5;241m10[39m, [38;5;241m15[39m, [38;5;241m20[39m,[38;5;241m25[39m]}

File [1;32m~\anaconda3\envs\mfdoc39\lib\site-packages\pandas\core\generic.py:5907[0m, in [0;36mNDFrame.__getattr__[1;34m(self, name)[0m
[0;32m   5900[0m [38;5;28;01mif[39;00m (
[0;32m   5901[0m     name [38;5;129;01mnot[39;00m [38;5;129;01min[39;00m [38;5;28mself[39m[38;5;241m.[39m_internal_names_set
[0;32m   5902[0m     [38;5;129;01mand[39;00m name [38;5;129;01mnot[39;00m [38;5;129;01min[39;00m [38;5;28mself[39m[38;5;241m.[39m_metadata
[0;32m   5903[0m     [38;5;129;01mand[39;00m name [38;5;129;01mnot[39;00m [38;5;129;01min[39;00m [38;5;28mself[39m[38;5;241m.[39m_accessors
[0;32m   5904[0m     [38;5;129;01mand[39;00m [38;5;28mself[39m[38;5;241m.[39m_info_axis[38;5;241m.[39m_can_hold_identifiers_and_holds_name(name)
[0;32m   5905[0m ):
[0;32m   5906[0m     [38;5;28;01mreturn[39;00m [38;5;28mself[39m[name]
[1;32m-> 5907[0m [38;5;28;01mreturn[39;00m [38;5;28;43mobject[39;49m[38;5;241;43m.[39;49m[38;5;21;43m__getattribute__[39;49m[43m([49m[38;5;28;43mself[39;49m[43m,[49m[43m [49m[43mname[49m[43m)[49m

[1;31mAttributeError[0m: 'DataFrame' object has no attribute 'upd'
AttributeError: 'DataFrame' object has no attribute 'upd'

